Workbook

Sheet Cover
B2: THE KRAFT HEINZ COMPANY (NASDAQ: KHC)
B3: Modelo Financiero - 5 años forward
B5: Prueba Tecnica | NoNighter LLC | Posicion: Modelador Financiero
B7: Fuente: | C7: 10-K FY2025 (fiscal year ended December 27, 2025) - SEC filing
B8: Periodo historico: | C8: FY2023A - FY2025A
B9: Periodo proyectado: | C9: FY2026E - FY2030E
B10: Moneda / unidades: | C10: USD millones (excepto excepciones)
B11: Convenciones de color: | C11: Hardcodes = azul (#0000FF) | Links entre sheets = verde (#3C7D22) | Formulas = negro
B13: Indice de hojas
B15: 1. Assumptions | C15: Drivers e hipotesis del modelo
B16: 2. Revenue | C16: Buildup de ingresos por segmento
B17: 3. COGS | C17: Buildup de costos por segmento
B18: 4. OpEx | C18: Buildup de SG&A
B19: 5. NWC | C19: Capital de trabajo (DSO / DIO / DPO)
B20: 6. CapEx_DA | C20: CapEx, Depreciacion y Amortizacion - roll forward PPE/Intangibles
B21: 7. Debt | C21: Debt schedule e interest expense
B22: 8. IS | C22: Estado de Resultados (P&L)
B23: 9. BS | C23: Balance General
B24: 10. CFS | C24: Estado de Flujos de Efectivo
B27: Notas y supuestos clave
B28: - Forecast de revenue por segmento: crecimiento anual aplicado al ultimo dato historico (FY25).
B29: - COGS proyectado como % de ventas por segmento (driver del 10-K = adjusted COGS de Note 21).
B30: - SG&A excluye impairments historicos. Se asume crecimiento anual modesto; impairments = 0 forward.
B31: - NWC proyectado con DSO/DIO/DPO; resto de partidas corrientes se mantienen flat.
B32: - CapEx y depreciacion proyectados como % de ventas; amortizacion de intangibles flat (~$250M/anio).
B33: - Debt: se asume refinanciacion del 100% de vencimientos (debt rollover); interes = tasa promedio aplicada al saldo promedio.
B34: - Impuestos: tax rate estatutaria efectiva proyectada ~25% (mix US + foreign).
B35: - Dividendos: se mantiene DPS de $1.60/accion (politica reciente FY23-FY25).
B36: - Cash se obtiene como plug desde el CFS; el Balance debe cerrar (ver fila Check en BS).

Sheet Assumptions
A1: ASSUMPTIONS - Drivers del modelo
A3: ($M) | B3: FY2023A | C3: FY2024A | D3: FY2025A | E3: FY2026E | F3: FY2027E | G3: FY2028E | H3: FY2029E | I3: FY2030E
A5: 1. Revenue growth (YoY %)
A6: North America - sales growth | C6: =Revenue!C6/Revenue!B6-1 -> -0.028967505 | D6: =Revenue!D6/Revenue!C6-1 -> -0.04896894 | E6: -0.02 | F6: 0.005 | G6: 0.015 | H6: 0.02 | I6: 0.025
A7: International Developed Markets - sales growth | C7: =Revenue!C7/Revenue!B7-1 -> -0.024289263 | D7: =Revenue!D7/Revenue!C7-1 -> 0.0011315417 | E7: 0.005 | F7: 0.015 | G7: 0.02 | H7: 0.025 | I7: 0.025
A8: Emerging Markets - sales growth | C8: =Revenue!C8/Revenue!B8-1 -> -0.042545832 | D8: =Revenue!D8/Revenue!C8-1 -> 0.017702312 | E8: 0.03 | F8: 0.04 | G8: 0.045 | H8: 0.05 | I8: 0.05
A10: 2. COGS as % of Sales (by segment)
A11: North America - COGS % sales | B11: =COGS!B6/Revenue!B6 -> 0.64334691 | C11: =COGS!C6/Revenue!C6 -> 0.63224684 | D11: =COGS!D6/Revenue!D6 -> 0.64973636 | E11: 0.65 | F11: 0.648 | G11: 0.645 | H11: 0.643 | I11: 0.64
A12: International Developed Markets - COGS % sales | B12: =COGS!B7/Revenue!B7 -> 0.71211703 | C12: =COGS!C7/Revenue!C7 -> 0.70212164 | D12: =COGS!D7/Revenue!D7 -> 0.70556654 | E12: 0.705 | F12: 0.702 | G12: 0.7 | H12: 0.698 | I12: 0.695
A13: Emerging Markets - COGS % sales | B13: =COGS!B8/Revenue!B8 -> 0.75613974 | C13: =COGS!C8/Revenue!C8 -> 0.73699422 | D13: =COGS!D8/Revenue!D8 -> 0.73127441 | E13: 0.73 | F13: 0.728 | G13: 0.725 | H13: 0.723 | I13: 0.72
A15: 3. OpEx (SG&A excl. impairments)
A16: SG&A growth (YoY %) | C16: =OpEx!C6/OpEx!B6-1 -> -0.020585049 | D16: =OpEx!D6/OpEx!C6-1 -> 0.015486726 | E16: 0.015 | F16: 0.02 | G16: 0.02 | H16: 0.025 | I16: 0.025
A17: SG&A as % of Sales (reference) | B17: =OpEx!B6/Revenue!B10 -> 0.13858859 | C17: =OpEx!C6/Revenue!C10 -> 0.13990559 | D17: =OpEx!D6/Revenue!D10 -> 0.14722155 | E17: =OpEx!E6/Revenue!E10 -> 0.15106221 | F17: =OpEx!F6/Revenue!F10 -> 0.15247369 | G17: =OpEx!G6/Revenue!G10 -> 0.15257021 | H17: =OpEx!H6/Revenue!H10 -> 0.15265263 | I17: =OpEx!I6/Revenue!I10 -> 0.15218062
A19: 4. NWC days (DSO / DIO / DPO)
A20: DSO - Days Sales Outstanding | C20: =NWC!C11 -> 30.320166 | D20: =NWC!D11 -> 32.984925 | E20: 33 | F20: 33 | G20: 33 | H20: 33 | I20: 33
A21: DIO - Days Inventory Outstanding | C21: =NWC!C12 -> 73.00865 | D21: =NWC!D12 -> 69.497685 | E21: 69 | F21: 68 | G21: 68 | H21: 67 | I21: 67
A22: DPO - Days Payable Outstanding | C22: =NWC!C13 -> 90.568788 | D22: =NWC!D13 -> 94.536163 | E22: 95 | F22: 95 | G22: 95 | H22: 95 | I22: 95
A24: 5. CapEx & D&A
A25: CapEx % of Sales | B25: =CapEx_DA!B6/Revenue!B10 -> 0.022672673 | C25: =CapEx_DA!C6/Revenue!C10 -> 0.024878124 | D25: =CapEx_DA!D6/Revenue!D10 -> 0.019926229 | E25: 0.034 | F25: 0.034 | G25: 0.033 | H25: 0.033 | I25: 0.032
A26: Depreciation % of Sales | B26: =CapEx_DA!B13/Revenue!B10 -> 0.026651652 | C26: =CapEx_DA!C13/Revenue!C10 -> 0.026928732 | D26: =CapEx_DA!D13/Revenue!D10 -> 0.028947157 | E26: 0.029 | F26: 0.029 | G26: 0.028 | H26: 0.028 | I26: 0.027
A27: Amortization of intangibles ($M) | B27: =CapEx_DA!B14 -> 251 | C27: =CapEx_DA!C14 -> 252 | D27: =CapEx_DA!D14 -> 246 | E27: 250 | F27: 250 | G27: 250 | H27: 250 | I27: 250
A29: 6. Debt
A30: Average interest rate on debt | D30: =Debt!D18/Debt!D17 -> 0.046096184 | E30: 0.046 | F30: 0.046 | G30: 0.046 | H30: 0.046 | I30: 0.046
A31: Refinancing % of scheduled maturities | E31: 1 | F31: 1 | G31: 1 | H31: 1 | I31: 1
A33: 7. Tax, Other & Equity
A34: Effective tax rate | B34: =IF(IS!B16<>0, IS!B17/IS!B16, 0) -> 0.21662538 | C34: =IF(IS!C16<>0, IS!C17/IS!C16, 0) -> -2.2079439 | D34: =IF(IS!D16<>0, IS!D17/IS!D16, 0) -> -0.074012856 | E34: 0.25 | F34: 0.25 | G34: 0.25 | H34: 0.25 | I34: 0.25
A35: Other (income)/expense ($M, flat) | E35: -100 | F35: -100 | G35: -100 | H35: -100 | I35: -100
A36: Dividends per share ($/share) | E36: 1.6 | F36: 1.6 | G36: 1.6 | H36: 1.6 | I36: 1.6
A37: Diluted shares outstanding (M) | E37: 1184 | F37: 1184 | G37: 1184 | H37: 1184 | I37: 1184
A38: Share repurchases ($M) | E38: 500 | F38: 500 | G38: 500 | H38: 500 | I38: 500

Sheet Revenue
A1: REVENUE BUILDUP - Net Sales by Segment
A3: ($M) | B3: FY2023A | C3: FY2024A | D3: FY2025A | E3: FY2026E | F3: FY2027E | G3: FY2028E | H3: FY2029E | I3: FY2030E
A5: Net sales by segment ($M)
A6: North America | B6: 20126 | C6: 19543 | D6: 18586 | E6: =D6*(1+Assumptions!E6) -> 18214.28 | F6: =E6*(1+Assumptions!F6) -> 18305.351 | G6: =F6*(1+Assumptions!G6) -> 18579.932 | H6: =G6*(1+Assumptions!H6) -> 18951.53 | I6: =H6*(1+Assumptions!I6) -> 19425.319
A7: International Developed Markets | B7: 3623 | C7: 3535 | D7: 3539 | E7: =D7*(1+Assumptions!E7) -> 3556.695 | F7: =E7*(1+Assumptions!F7) -> 3610.0454 | G7: =F7*(1+Assumptions!G7) -> 3682.2463 | H7: =G7*(1+Assumptions!H7) -> 3774.3025 | I7: =H7*(1+Assumptions!I7) -> 3868.6601
A8: Emerging Markets | B8: 2891 | C8: 2768 | D8: 2817 | E8: =D8*(1+Assumptions!E8) -> 2901.51 | F8: =E8*(1+Assumptions!F8) -> 3017.5704 | G8: =F8*(1+Assumptions!G8) -> 3153.3611 | H8: =G8*(1+Assumptions!H8) -> 3311.0291 | I8: =H8*(1+Assumptions!I8) -> 3476.5806
A10: Total Net Sales | B10: =SUM(B6:B8) -> 26640 | C10: =SUM(C6:C8) -> 25846 | D10: =SUM(D6:D8) -> 24942 | E10: =SUM(E6:E8) -> 24672.485 | F10: =SUM(F6:F8) -> 24932.967 | G10: =SUM(G6:G8) -> 25415.539 | H10: =SUM(H6:H8) -> 26036.862 | I10: =SUM(I6:I8) -> 26770.559
A12: Growth rates YoY (check)
A13: North America | C13: =C6/B6-1 -> -0.028967505 | D13: =D6/C6-1 -> -0.04896894 | E13: =E6/D6-1 -> -0.02 | F13: =F6/E6-1 -> 0.005 | G13: =G6/F6-1 -> 0.015 | H13: =H6/G6-1 -> 0.02 | I13: =I6/H6-1 -> 0.025
A14: International Developed Markets | C14: =C7/B7-1 -> -0.024289263 | D14: =D7/C7-1 -> 0.0011315417 | E14: =E7/D7-1 -> 0.005 | F14: =F7/E7-1 -> 0.015 | G14: =G7/F7-1 -> 0.02 | H14: =H7/G7-1 -> 0.025 | I14: =I7/H7-1 -> 0.025
A15: Emerging Markets | C15: =C8/B8-1 -> -0.042545832 | D15: =D8/C8-1 -> 0.017702312 | E15: =E8/D8-1 -> 0.03 | F15: =F8/E8-1 -> 0.04 | G15: =G8/F8-1 -> 0.045 | H15: =H8/G8-1 -> 0.05 | I15: =I8/H8-1 -> 0.05
A16: Total Kraft Heinz | C16: =C10/B10-1 -> -0.029804805 | D16: =D10/C10-1 -> -0.034976399 | E16: =E10/D10-1 -> -0.010805669 | F16: =F10/E10-1 -> 0.0105576 | G16: =G10/F10-1 -> 0.01935477 | H16: =H10/G10-1 -> 0.024446574 | I16: =I10/H10-1 -> 0.028179175

Sheet COGS
A1: COGS BUILDUP - by Segment (% of Sales)
A3: ($M) | B3: FY2023A | C3: FY2024A | D3: FY2025A | E3: FY2026E | F3: FY2027E | G3: FY2028E | H3: FY2029E | I3: FY2030E
A5: COGS by segment ($M)
A6: North America | B6: 12948 | C6: 12356 | D6: 12076 | E6: =Revenue!E6*Assumptions!E11 -> 11839.282 | F6: =Revenue!F6*Assumptions!F11 -> 11861.868 | G6: =Revenue!G6*Assumptions!G11 -> 11984.056 | H6: =Revenue!H6*Assumptions!H11 -> 12185.834 | I6: =Revenue!I6*Assumptions!I11 -> 12432.204
A7: International Developed Markets | B7: 2580 | C7: 2482 | D7: 2497 | E7: =Revenue!E7*Assumptions!E12 -> 2507.47 | F7: =Revenue!F7*Assumptions!F12 -> 2534.2519 | G7: =Revenue!G7*Assumptions!G12 -> 2577.5724 | H7: =Revenue!H7*Assumptions!H12 -> 2634.4631 | I7: =Revenue!I7*Assumptions!I12 -> 2688.7187
A8: Emerging Markets | B8: 2186 | C8: 2040 | D8: 2060 | E8: =Revenue!E8*Assumptions!E13 -> 2118.1023 | F8: =Revenue!F8*Assumptions!F13 -> 2196.7913 | G8: =Revenue!G8*Assumptions!G13 -> 2286.1868 | H8: =Revenue!H8*Assumptions!H13 -> 2393.8741 | I8: =Revenue!I8*Assumptions!I13 -> 2503.138
A10: Total COGS | B10: =SUM(B6:B8) -> 17714 | C10: =SUM(C6:C8) -> 16878 | D10: =SUM(D6:D8) -> 16633 | E10: =SUM(E6:E8) -> 16464.854 | F10: =SUM(F6:F8) -> 16592.911 | G10: =SUM(G6:G8) -> 16847.815 | H10: =SUM(H6:H8) -> 17214.171 | I10: =SUM(I6:I8) -> 17624.061
A12: COGS as % of Segment Sales (check)
A13: North America | B13: =B6/Revenue!B6 -> 0.64334691 | C13: =C6/Revenue!C6 -> 0.63224684 | D13: =D6/Revenue!D6 -> 0.64973636 | E13: =E6/Revenue!E6 -> 0.65 | F13: =F6/Revenue!F6 -> 0.648 | G13: =G6/Revenue!G6 -> 0.645 | H13: =H6/Revenue!H6 -> 0.643 | I13: =I6/Revenue!I6 -> 0.64
A14: International Developed Markets | B14: =B7/Revenue!B7 -> 0.71211703 | C14: =C7/Revenue!C7 -> 0.70212164 | D14: =D7/Revenue!D7 -> 0.70556654 | E14: =E7/Revenue!E7 -> 0.705 | F14: =F7/Revenue!F7 -> 0.702 | G14: =G7/Revenue!G7 -> 0.7 | H14: =H7/Revenue!H7 -> 0.698 | I14: =I7/Revenue!I7 -> 0.695
A15: Emerging Markets | B15: =B8/Revenue!B8 -> 0.75613974 | C15: =C8/Revenue!C8 -> 0.73699422 | D15: =D8/Revenue!D8 -> 0.73127441 | E15: =E8/Revenue!E8 -> 0.73 | F15: =F8/Revenue!F8 -> 0.728 | G15: =G8/Revenue!G8 -> 0.725 | H15: =H8/Revenue!H8 -> 0.723 | I15: =I8/Revenue!I8 -> 0.72
A17: Gross margin % (consolidated) | B17: =1-B10/Revenue!B10 -> 0.33506006 | C17: =1-C10/Revenue!C10 -> 0.34697826 | D17: =1-D10/Revenue!D10 -> 0.33313287 | E17: =1-E10/Revenue!E10 -> 0.33266332 | F17: =1-F10/Revenue!F10 -> 0.33449915 | G17: =1-G10/Revenue!G10 -> 0.33710573 | H17: =1-H10/Revenue!H10 -> 0.33885384 | I17: =1-I10/Revenue!I10 -> 0.34166259

Sheet OpEx
A1: OPEX BUILDUP - SG&A (excluding impairments)
A3: ($M) | B3: FY2023A | C3: FY2024A | D3: FY2025A | E3: FY2026E | F3: FY2027E | G3: FY2028E | H3: FY2029E | I3: FY2030E
A5: SG&A excluding impairment losses ($M)
A6: SG&A (excl. impairments) | B6: 3692 | C6: 3616 | D6: 3672 | E6: =D6*(1+Assumptions!E16) -> 3727.08 | F6: =E6*(1+Assumptions!F16) -> 3801.6216 | G6: =F6*(1+Assumptions!G16) -> 3877.654 | H6: =G6*(1+Assumptions!H16) -> 3974.5954 | I6: =H6*(1+Assumptions!I16) -> 4073.9603
A8: SG&A growth YoY | C8: =C6/B6-1 -> -0.020585049 | D8: =D6/C6-1 -> 0.015486726 | E8: =E6/D6-1 -> 0.015 | F8: =F6/E6-1 -> 0.02 | G8: =G6/F6-1 -> 0.02 | H8: =H6/G6-1 -> 0.025 | I8: =I6/H6-1 -> 0.025
A9: SG&A as % of Sales | B9: =B6/Revenue!B10 -> 0.13858859 | C9: =C6/Revenue!C10 -> 0.13990559 | D9: =D6/Revenue!D10 -> 0.14722155 | E9: =E6/Revenue!E10 -> 0.15106221 | F9: =F6/Revenue!F10 -> 0.15247369 | G9: =G6/Revenue!G10 -> 0.15257021 | H9: =H6/Revenue!H10 -> 0.15265263 | I9: =I6/Revenue!I10 -> 0.15218062

Sheet NWC
A1: NET WORKING CAPITAL BUILDUP (DSO / DIO / DPO)
A3: ($M) | B3: FY2023A | C3: FY2024A | D3: FY2025A | E3: FY2026E | F3: FY2027E | G3: FY2028E | H3: FY2029E | I3: FY2030E
A5: Working capital balance ($M)
A6: Trade receivables (AR) | C6: 2147 | D6: 2254 | E6: =Assumptions!E20*Revenue!E10/365 -> 2230.663 | F6: =Assumptions!F20*Revenue!F10/365 -> 2254.2135 | G6: =Assumptions!G20*Revenue!G10/365 -> 2297.8433 | H6: =Assumptions!H20*Revenue!H10/365 -> 2354.0177 | I6: =Assumptions!I20*Revenue!I10/365 -> 2420.3519
A7: Inventories | C7: 3376 | D7: 3167 | E7: =Assumptions!E21*COGS!E10/365 -> 3112.5341 | F7: =Assumptions!F21*COGS!F10/365 -> 3091.282 | G7: =Assumptions!G21*COGS!G10/365 -> 3138.771 | H7: =Assumptions!H21*COGS!H10/365 -> 3159.8616 | I7: =Assumptions!I21*COGS!I10/365 -> 3235.1015
A8: Accounts payable | C8: 4188 | D8: 4308 | E8: =Assumptions!E22*COGS!E10/365 -> 4285.373 | F8: =Assumptions!F22*COGS!F10/365 -> 4318.7028 | G8: =Assumptions!G22*COGS!G10/365 -> 4385.0478 | H8: =Assumptions!H22*COGS!H10/365 -> 4480.4007 | I8: =Assumptions!I22*COGS!I10/365 -> 4587.0843
A9: Operating NWC (AR + Inv - AP) | B9: =B6+B7-B8 -> 0 | C9: =C6+C7-C8 -> 1335 | D9: =D6+D7-D8 -> 1113 | E9: =E6+E7-E8 -> 1057.8241 | F9: =F6+F7-F8 -> 1026.7927 | G9: =G6+G7-G8 -> 1051.5665 | H9: =H6+H7-H8 -> 1033.4785 | I9: =I6+I7-I8 -> 1068.3692
A10: Implied days (check)
A11: DSO = AR / Sales * 365 | B11: =IFERROR(B6/Revenue!B10*365,0) -> 0 | C11: =IFERROR(C6/Revenue!C10*365,0) -> 30.320166 | D11: =IFERROR(D6/Revenue!D10*365,0) -> 32.984925 | E11: =IFERROR(E6/Revenue!E10*365,0) -> 33 | F11: =IFERROR(F6/Revenue!F10*365,0) -> 33 | G11: =IFERROR(G6/Revenue!G10*365,0) -> 33 | H11: =IFERROR(H6/Revenue!H10*365,0) -> 33 | I11: =IFERROR(I6/Revenue!I10*365,0) -> 33
A12: DIO = Inv / COGS * 365 | B12: =IFERROR(B7/COGS!B10*365,0) -> 0 | C12: =IFERROR(C7/COGS!C10*365,0) -> 73.00865 | D12: =IFERROR(D7/COGS!D10*365,0) -> 69.497685 | E12: =IFERROR(E7/COGS!E10*365,0) -> 69 | F12: =IFERROR(F7/COGS!F10*365,0) -> 68 | G12: =IFERROR(G7/COGS!G10*365,0) -> 68 | H12: =IFERROR(H7/COGS!H10*365,0) -> 67 | I12: =IFERROR(I7/COGS!I10*365,0) -> 67
A13: DPO = AP / COGS * 365 | B13: =IFERROR(B8/COGS!B10*365,0) -> 0 | C13: =IFERROR(C8/COGS!C10*365,0) -> 90.568788 | D13: =IFERROR(D8/COGS!D10*365,0) -> 94.536163 | E13: =IFERROR(E8/COGS!E10*365,0) -> 95 | F13: =IFERROR(F8/COGS!F10*365,0) -> 95 | G13: =IFERROR(G8/COGS!G10*365,0) -> 95 | H13: =IFERROR(H8/COGS!H10*365,0) -> 95 | I13: =IFERROR(I8/COGS!I10*365,0) -> 95
A15: Change in NWC ($M) - flows to CFS
A16: (Increase) / decrease in AR | C16: =-(C6-B6) -> -2147 | D16: =-(D6-C6) -> -107 | E16: =-(E6-D6) -> 23.336973 | F16: =-(F6-E6) -> -23.550448 | G16: =-(G6-F6) -> -43.629783 | H16: =-(H6-G6) -> -56.174394 | I16: =-(I6-H6) -> -66.334274
A17: (Increase) / decrease in Inventories | C17: =-(C7-B7) -> -3376 | D17: =-(D7-C7) -> 209 | E17: =-(E7-D7) -> 54.465904 | F17: =-(F7-E7) -> 21.252075 | G17: =-(G7-F7) -> -47.489018 | H17: =-(H7-G7) -> -21.09052 | I17: =-(I7-H7) -> -75.239982
A18: Increase / (decrease) in AP | C18: =C8-B8 -> 4188 | D18: =D8-C8 -> 120 | E18: =E8-D8 -> -22.62697 | F18: =F8-E8 -> 33.329793 | G18: =G8-F8 -> 66.344952 | H18: =H8-G8 -> 95.352943 | I18: =I8-H8 -> 106.68356
A19: Total change in operating NWC | C19: =SUM(C16:C18) -> -1335 | D19: =SUM(D16:D18) -> 222 | E19: =SUM(E16:E18) -> 55.175907 | F19: =SUM(F16:F18) -> 31.03142 | G19: =SUM(G16:G18) -> -24.77385 | H19: =SUM(H16:H18) -> 18.088029 | I19: =SUM(I16:I18) -> -34.8907

Sheet CapEx_DA
A1: CAPEX & D&A BUILDUP - Roll-forward of PPE and Intangibles
A3: ($M) | B3: FY2023A | C3: FY2024A | D3: FY2025A | E3: FY2026E | F3: FY2027E | G3: FY2028E | H3: FY2029E | I3: FY2030E
A5: CapEx by segment ($M)
A6: North America | B6: 604 | C6: 643 | D6: 497 | E6: =E10*(D6/D10) -> 520.49395 | F6: =F10*(D6/D10) -> 525.98911 | G6: =G10*(D6/D10) -> 520.39982 | H6: =H10*(D6/D10) -> 533.12181 | I6: =I10*(D6/D10) -> 531.5343
A7: International Developed Markets | B7: 178 | C7: 154 | D7: 112 | E7: =E10*(D7/D10) -> 117.29441 | F7: =F10*(D7/D10) -> 118.53276 | G7: =G10*(D7/D10) -> 117.2732 | H7: =H10*(D7/D10) -> 120.14013 | I7: =I10*(D7/D10) -> 119.78238
A8: Emerging Markets | B8: 163 | C8: 115 | D8: 105 | E8: =E10*(D8/D10) -> 109.96351 | F8: =F10*(D8/D10) -> 111.12446 | G8: =G10*(D8/D10) -> 109.94362 | H8: =H10*(D8/D10) -> 112.63137 | I8: =I10*(D8/D10) -> 112.29598
A9: General corporate | B9: 68 | C9: 112 | D9: 87 | E9: =E10*(D9/D10) -> 91.112623 | F9: =F10*(D9/D10) -> 92.074553 | G9: =G10*(D9/D10) -> 91.096146 | H9: =H10*(D9/D10) -> 93.323134 | I9: =I10*(D9/D10) -> 93.045239
A10: Total CapEx | B10: =SUM(B6:B9) -> 1013 | C10: =SUM(C6:C9) -> 1024 | D10: =SUM(D6:D9) -> 801 | E10: =Assumptions!E25*Revenue!E10 -> 838.86449 | F10: =Assumptions!F25*Revenue!F10 -> 847.72089 | G10: =Assumptions!G25*Revenue!G10 -> 838.71279 | H10: =Assumptions!H25*Revenue!H10 -> 859.21644 | I10: =Assumptions!I25*Revenue!I10 -> 856.65789
A12: Depreciation & Amortization ($M)
A13: Depreciation (PPE) | B13: 710 | C13: 696 | D13: 722 | E13: =Assumptions!E26*Revenue!E10 -> 715.50207 | F13: =Assumptions!F26*Revenue!F10 -> 723.05605 | G13: =Assumptions!G26*Revenue!G10 -> 711.63509 | H13: =Assumptions!H26*Revenue!H10 -> 729.03213 | I13: =Assumptions!I26*Revenue!I10 -> 722.8051
A14: Amortization of intangibles | B14: 251 | C14: 252 | D14: 246 | E14: =Assumptions!E27 -> 250 | F14: =Assumptions!F27 -> 250 | G14: =Assumptions!G27 -> 250 | H14: =Assumptions!H27 -> 250 | I14: =Assumptions!I27 -> 250
A15: Total D&A | B15: =B13+B14 -> 961 | C15: =C13+C14 -> 948 | D15: =D13+D14 -> 968 | E15: =E13+E14 -> 965.50207 | F15: =F13+F14 -> 973.05605 | G15: =G13+G14 -> 961.63509 | H15: =H13+H14 -> 979.03213 | I15: =I13+I14 -> 972.8051
A17: PPE roll-forward ($M)
A18: Beginning PPE, net | E18: =D21 -> 7318 | F18: =E21 -> 7441.3624 | G18: =F21 -> 7566.0273 | H18: =G21 -> 7693.105 | I18: =H21 -> 7823.2893
A19: (+) CapEx | E19: =E10 -> 838.86449 | F19: =F10 -> 847.72089 | G19: =G10 -> 838.71279 | H19: =H10 -> 859.21644 | I19: =I10 -> 856.65789
A20: (-) Depreciation | E20: =-E13 -> -715.50207 | F20: =-F13 -> -723.05605 | G20: =-G13 -> -711.63509 | H20: =-H13 -> -729.03213 | I20: =-I13 -> -722.8051
A21: Ending PPE, net | C21: 7152 | D21: 7318 | E21: =SUM(E18:E20) -> 7441.3624 | F21: =SUM(F18:F20) -> 7566.0273 | G21: =SUM(G18:G20) -> 7693.105 | H21: =SUM(H18:H20) -> 7823.2893 | I21: =SUM(I18:I20) -> 7957.1421
A23: Intangibles roll-forward ($M)
A24: Beginning Intangibles, net | E24: =D26 -> 37529 | F24: =E26 -> 37279 | G24: =F26 -> 37029 | H24: =G26 -> 36779 | I24: =H26 -> 36529
A25: (-) Amortization | E25: =-E14 -> -250 | F25: =-F14 -> -250 | G25: =-G14 -> -250 | H25: =-H14 -> -250 | I25: =-I14 -> -250
A26: Ending Intangibles, net | C26: 40099 | D26: 37529 | E26: =E24+E25 -> 37279 | F26: =F24+F25 -> 37029 | G26: =G24+G25 -> 36779 | H26: =H24+H25 -> 36529 | I26: =I24+I25 -> 36279
A30: Nota metodológica:
A31: El roll-forward de activos intangibles refleja únicamente la amortización anual proyectada (en torno a $250M), sin incorporar nuevas adquisiciones. Este supuesto se basa en que KHC se encuentra en una etapa de desinversión y reestructuración de portfolio, con foco en reducción de deuda y mejora de márgenes operativos, lo que hace poco probable la realización de adquisiciones significativas en el período proyectado. En adición, El ratio CapEx/Ventas se incrementa de 2,0% histórico (FY2025A) a 3,4% en FY2026E-FY2027E, reflejando un ciclo de reinversión moderado luego de un año de contención de gastos de capital. Los niveles proyectados son consistentes con el promedio histórico FY2023A-FY2024A (~2,3%-2,5%) más un margen adicional por proyectos de eficiencia operativa mencionados (ver 10-K).

Sheet Debt
A1: DEBT SCHEDULE - Total Debt roll-forward & Interest Expense
A3: ($M) | B3: FY2023A | C3: FY2024A | D3: FY2025A | E3: FY2026E | F3: FY2027E | G3: FY2028E | H3: FY2029E | I3: FY2030E
A5: Total debt roll-forward ($M)
A6: Beginning total debt (CurLTD + LTD) | E6: =D10 -> 21219 | F6: =E10 -> 21219 | G6: =F10 -> 21219 | H6: =G10 -> 21219 | I6: =H10 -> 21219
A7: (-) Scheduled maturities (10-K Note 17) | E7: -1879 | F7: -1893 | G7: -1679 | H7: -1009 | I7: -915
A8: (+) New debt issuance (refinancing) | E8: =-E7*Assumptions!E31 -> 1879 | F8: =-F7*Assumptions!F31 -> 1893 | G8: =-G7*Assumptions!G31 -> 1679 | H8: =-H7*Assumptions!H31 -> 1009 | I8: =-I7*Assumptions!I31 -> 915
A9: (+/-) FX / debt premium amortization (held flat) | E9: 0 | F9: 0 | G9: 0 | H9: 0 | I9: 0
A10: Ending total debt | C10: 19869 | D10: 21219 | E10: =SUM(E6:E9) -> 21219 | F10: =SUM(F6:F9) -> 21219 | G10: =SUM(G6:G9) -> 21219 | H10: =SUM(H6:H9) -> 21219 | I10: =SUM(I6:I9) -> 21219
A12: Current vs Long-term split ($M)
A13: Current portion of LT debt | C13: 654 | D13: 1908 | E13: 1893 | F13: 1679 | G13: 1009 | H13: 915 | I13: 915
A14: Long-term debt | C14: 19215 | D14: 19311 | E14: =E10-E13 -> 19326 | F14: =F10-F13 -> 19540 | G14: =G10-G13 -> 20210 | H14: =H10-H13 -> 20304 | I14: =I10-I13 -> 20304
A16: Interest expense ($M)
A17: Average total debt | D17: =AVERAGE(C10,D10) -> 20544 | E17: =AVERAGE(E6,E10) -> 21219 | F17: =AVERAGE(F6,F10) -> 21219 | G17: =AVERAGE(G6,G10) -> 21219 | H17: =AVERAGE(H6,H10) -> 21219 | I17: =AVERAGE(I6,I10) -> 21219
A18: Interest expense | B18: 912 | C18: 912 | D18: 947 | E18: =E17*Assumptions!E30 -> 976.074 | F18: =F17*Assumptions!F30 -> 976.074 | G18: =G17*Assumptions!G30 -> 976.074 | H18: =H17*Assumptions!H30 -> 976.074 | I18: =I17*Assumptions!I30 -> 976.074

Sheet IS
A1: INCOME STATEMENT (P&L) - Consolidated
A3: ($M) | B3: FY2023A | C3: FY2024A | D3: FY2025A | E3: FY2026E | F3: FY2027E | G3: FY2028E | H3: FY2029E | I3: FY2030E
A5: Consolidated Income Statement ($M)
A6: Net sales | B6: =Revenue!B10 -> 26640 | C6: =Revenue!C10 -> 25846 | D6: =Revenue!D10 -> 24942 | E6: =Revenue!E10 -> 24672.485 | F6: =Revenue!F10 -> 24932.967 | G6: =Revenue!G10 -> 25415.539 | H6: =Revenue!H10 -> 26036.862 | I6: =Revenue!I10 -> 26770.559
A7: Cost of products sold | B7: =-COGS!B10 -> -17714 | C7: =-COGS!C10 -> -16878 | D7: =-COGS!D10 -> -16633 | E7: =-COGS!E10 -> -16464.854 | F7: =-COGS!F10 -> -16592.911 | G7: =-COGS!G10 -> -16847.815 | H7: =-COGS!H10 -> -17214.171 | I7: =-COGS!I10 -> -17624.061
A8: Gross profit | B8: =B6+B7 -> 8926 | C8: =C6+C7 -> 8968 | D8: =D6+D7 -> 8309 | E8: =E6+E7 -> 8207.6307 | F8: =F6+F7 -> 8340.0564 | G8: =G6+G7 -> 8567.7239 | H8: =H6+H7 -> 8822.6907 | I8: =I6+I7 -> 9146.4986
A9: Selling, general & administrative expense | B9: =-OpEx!B6 -> -3692 | C9: =-OpEx!C6 -> -3616 | D9: =-OpEx!D6 -> -3672 | E9: =-OpEx!E6 -> -3727.08 | F9: =-OpEx!F6 -> -3801.6216 | G9: =-OpEx!G6 -> -3877.654 | H9: =-OpEx!H6 -> -3974.5954 | I9: =-OpEx!I6 -> -4073.9603
A10: Goodwill impairment losses | B10: -510 | C10: -1638 | D10: -6734 | E10: 0 | F10: 0 | G10: 0 | H10: 0 | I10: 0
A11: Intangible asset impairment losses | B11: -152 | C11: -2031 | D11: -2572 | E11: 0 | F11: 0 | G11: 0 | H11: 0 | I11: 0
A12: Operating income / (loss) | B12: =B8+B9+B10+B11 -> 4572 | C12: =C8+C9+C10+C11 -> 1683 | D12: =D8+D9+D10+D11 -> -4669 | E12: =E8+E9+E10+E11 -> 4480.5507 | F12: =F8+F9+F10+F11 -> 4538.4348 | G12: =G8+G9+G10+G11 -> 4690.0699 | H12: =H8+H9+H10+H11 -> 4848.0954 | I12: =I8+I9+I10+I11 -> 5072.5383
A14: Interest expense | B14: =-Debt!B18 -> -912 | C14: =-Debt!C18 -> -912 | D14: =-Debt!D18 -> -947 | E14: =-Debt!E18 -> -976.074 | F14: =-Debt!F18 -> -976.074 | G14: =-Debt!G18 -> -976.074 | H14: =-Debt!H18 -> -976.074 | I14: =-Debt!I18 -> -976.074
A15: Other (expense) / income | B15: -27 | C15: 85 | D15: 171 | E15: =-Assumptions!E35 -> 100 | F15: =-Assumptions!F35 -> 100 | G15: =-Assumptions!G35 -> 100 | H15: =-Assumptions!H35 -> 100 | I15: =-Assumptions!I35 -> 100
A16: Income / (loss) before income taxes | B16: =B12+B14+B15 -> 3633 | C16: =C12+C14+C15 -> 856 | D16: =D12+D14+D15 -> -5445 | E16: =E12+E14+E15 -> 3604.4767 | F16: =F12+F14+F15 -> 3662.3608 | G16: =G12+G14+G15 -> 3813.9959 | H16: =H12+H14+H15 -> 3972.0214 | I16: =I12+I14+I15 -> 4196.4643
A17: Provision for / (benefit from) income taxes | B17: 787 | C17: -1890 | D17: 403 | E17: =E16*Assumptions!E34 -> 901.11918 | F17: =F16*Assumptions!F34 -> 915.59019 | G17: =G16*Assumptions!G34 -> 953.49898 | H17: =H16*Assumptions!H34 -> 993.00534 | I17: =I16*Assumptions!I34 -> 1049.1161
A18: Net income / (loss) | B18: =B16-B17 -> 2846 | C18: =C16-C17 -> 2746 | D18: =D16-D17 -> -5848 | E18: =E16-E17 -> 2703.3575 | F18: =F16-F17 -> 2746.7706 | G18: =G16-G17 -> 2860.4969 | H18: =H16-H17 -> 2979.016 | I18: =I16-I17 -> 3147.3482
A20: Margins & EPS (check)
A21: Gross margin % | B21: =B8/B6 -> 0.33506006 | C21: =C8/C6 -> 0.34697826 | D21: =D8/D6 -> 0.33313287 | E21: =E8/E6 -> 0.33266332 | F21: =F8/F6 -> 0.33449915 | G21: =G8/G6 -> 0.33710573 | H21: =H8/H6 -> 0.33885384 | I21: =I8/I6 -> 0.34166259
A22: Operating margin % | B22: =B12/B6 -> 0.17162162 | C22: =C12/C6 -> 0.065116459 | D22: =D12/D6 -> -0.18719429 | E22: =E12/E6 -> 0.18160111 | F22: =F12/F6 -> 0.18202546 | G22: =G12/G6 -> 0.18453553 | H22: =H12/H6 -> 0.18620122 | I22: =I12/I6 -> 0.18948197
A23: Net margin % | B23: =B18/B6 -> 0.10683183 | C23: =C18/C6 -> 0.10624468 | D23: =D18/D6 -> -0.23446396 | E23: =E18/E6 -> 0.10956973 | F23: =F18/F6 -> 0.11016621 | G23: =G18/G6 -> 0.11254913 | H23: =H18/H6 -> 0.11441532 | I23: =I18/I6 -> 0.11756752
A24: EPS - basic ($) | B24: 2.33 | C24: 2.27 | D24: -4.93 | E24: =E18/Assumptions!E37 -> 2.2832412 | F24: =F18/Assumptions!F37 -> 2.3199076 | G24: =G18/Assumptions!G37 -> 2.4159602 | H24: =H18/Assumptions!H37 -> 2.5160608 | I24: =I18/Assumptions!I37 -> 2.6582333

Sheet BS
A1: BALANCE SHEET - Consolidated
A3: ($M) | B3: FY2023A | C3: FY2024A | D3: FY2025A | E3: FY2026E | F3: FY2027E | G3: FY2028E | H3: FY2029E | I3: FY2030E
A5: ASSETS ($M)
A6: Cash and cash equivalents | C6: 1334 | D6: 2615 | E6: =CFS!E29 -> 3249.771 | F6: =CFS!F29 -> 3758.5082 | G6: =CFS!G29 -> 4322.7536 | H6: =CFS!H29 -> 5045.2733 | I6: =CFS!I29 -> 5879.478
A7: Trade receivables, net | C7: 2147 | D7: 2254 | E7: =NWC!E6 -> 2230.663 | F7: =NWC!F6 -> 2254.2135 | G7: =NWC!G6 -> 2297.8433 | H7: =NWC!H6 -> 2354.0177 | I7: =NWC!I6 -> 2420.3519
A8: Inventories | C8: 3376 | D8: 3167 | E8: =NWC!E7 -> 3112.5341 | F8: =NWC!F7 -> 3091.282 | G8: =NWC!G7 -> 3138.771 | H8: =NWC!H7 -> 3159.8616 | I8: =NWC!I7 -> 3235.1015
A9: Prepaid expenses | C9: 215 | D9: 291 | E9: =D9 -> 291 | F9: =E9 -> 291 | G9: =F9 -> 291 | H9: =G9 -> 291 | I9: =H9 -> 291
A10: Marketable securities | C10: 0 | D10: 1060 | E10: =D10 -> 1060 | F10: =E10 -> 1060 | G10: =F10 -> 1060 | H10: =G10 -> 1060 | I10: =H10 -> 1060
A11: Other current assets | C11: 583 | D11: 588 | E11: =D11 -> 588 | F11: =E11 -> 588 | G11: =F11 -> 588 | H11: =G11 -> 588 | I11: =H11 -> 588
A12: Assets held for sale | C12: 0 | D12: 152 | E12: 0 | F12: =E12 -> 0 | G12: =F12 -> 0 | H12: =G12 -> 0 | I12: =H12 -> 0
A13: Total current assets | B13: =SUM(B6:B12) -> 0 | C13: =SUM(C6:C12) -> 7655 | D13: =SUM(D6:D12) -> 10127 | E13: =SUM(E6:E12) -> 10531.968 | F13: =SUM(F6:F12) -> 11043.004 | G13: =SUM(G6:G12) -> 11698.368 | H13: =SUM(H6:H12) -> 12498.153 | I13: =SUM(I6:I12) -> 13473.932
A14: Property, plant and equipment, net | C14: 7152 | D14: 7318 | E14: =CapEx_DA!E21 -> 7441.3624 | F14: =CapEx_DA!F21 -> 7566.0273 | G14: =CapEx_DA!G21 -> 7693.105 | H14: =CapEx_DA!H21 -> 7823.2893 | I14: =CapEx_DA!I21 -> 7957.1421
A15: Goodwill | C15: 28673 | D15: 22179 | E15: =D15 -> 22179 | F15: =E15 -> 22179 | G15: =F15 -> 22179 | H15: =G15 -> 22179 | I15: =H15 -> 22179
A16: Intangible assets, net | C16: 40099 | D16: 37529 | E16: =CapEx_DA!E26 -> 37279 | F16: =CapEx_DA!F26 -> 37029 | G16: =CapEx_DA!G26 -> 36779 | H16: =CapEx_DA!H26 -> 36529 | I16: =CapEx_DA!I26 -> 36279
A17: Other non-current assets | C17: 4708 | D17: 4633 | E17: =D17 -> 4633 | F17: =E17 -> 4633 | G17: =F17 -> 4633 | H17: =G17 -> 4633 | I17: =H17 -> 4633
A18: TOTAL ASSETS | B18: =B13+B14+B15+B16+B17 -> 0 | C18: =C13+C14+C15+C16+C17 -> 88287 | D18: =D13+D14+D15+D16+D17 -> 81786 | E18: =E13+E14+E15+E16+E17 -> 82064.331 | F18: =F13+F14+F15+F16+F17 -> 82450.031 | G18: =G13+G14+G15+G16+G17 -> 82982.473 | H18: =H13+H14+H15+H16+H17 -> 83662.442 | I18: =I13+I14+I15+I16+I17 -> 84522.074
A20: LIABILITIES ($M)
A21: Current portion of long-term debt | C21: 654 | D21: 1908 | E21: =Debt!E13 -> 1893 | F21: =Debt!F13 -> 1679 | G21: =Debt!G13 -> 1009 | H21: =Debt!H13 -> 915 | I21: =Debt!I13 -> 915
A22: Accounts payable | C22: 4188 | D22: 4308 | E22: =NWC!E8 -> 4285.373 | F22: =NWC!F8 -> 4318.7028 | G22: =NWC!G8 -> 4385.0478 | H22: =NWC!H8 -> 4480.4007 | I22: =NWC!I8 -> 4587.0843
A23: Accrued marketing | C23: 697 | D23: 801 | E23: =D23 -> 801 | F23: =E23 -> 801 | G23: =F23 -> 801 | H23: =G23 -> 801 | I23: =H23 -> 801
A24: Interest payable | C24: 263 | D24: 298 | E24: =D24 -> 298 | F24: =E24 -> 298 | G24: =F24 -> 298 | H24: =G24 -> 298 | I24: =H24 -> 298
A25: Other current liabilities | C25: 1451 | D25: 1455 | E25: =D25 -> 1455 | F25: =E25 -> 1455 | G25: =F25 -> 1455 | H25: =G25 -> 1455 | I25: =H25 -> 1455
A26: Liabilities held for sale | C26: 0 | D26: 8 | E26: 0 | F26: =E26 -> 0 | G26: =F26 -> 0 | H26: =G26 -> 0 | I26: =H26 -> 0
A27: Total current liabilities | B27: =SUM(B21:B26) -> 0 | C27: =SUM(C21:C26) -> 7253 | D27: =SUM(D21:D26) -> 8778 | E27: =SUM(E21:E26) -> 8732.373 | F27: =SUM(F21:F26) -> 8551.7028 | G27: =SUM(G21:G26) -> 7948.0478 | H27: =SUM(H21:H26) -> 7949.4007 | I27: =SUM(I21:I26) -> 8056.0843
A28: Long-term debt | C28: 19215 | D28: 19311 | E28: =Debt!E14 -> 19326 | F28: =Debt!F14 -> 19540 | G28: =Debt!G14 -> 20210 | H28: =Debt!H14 -> 20304 | I28: =Debt!I14 -> 20304
A29: Deferred income taxes | C29: 9679 | D29: 9022 | E29: =D29 -> 9022 | F29: =E29 -> 9022 | G29: =F29 -> 9022 | H29: =G29 -> 9022 | I29: =H29 -> 9022
A30: Accrued postemployment costs | C30: 135 | D30: 131 | E30: =D30 -> 131 | F30: =E30 -> 131 | G30: =F30 -> 131 | H30: =G30 -> 131 | I30: =H30 -> 131
A31: Long-term deferred income | C31: 1374 | D31: 1321 | E31: =D31 -> 1321 | F31: =E31 -> 1321 | G31: =F31 -> 1321 | H31: =G31 -> 1321 | I31: =H31 -> 1321
A32: Other non-current liabilities | C32: 1306 | D32: 1434 | E32: =D32 -> 1434 | F32: =E32 -> 1434 | G32: =F32 -> 1434 | H32: =G32 -> 1434 | I32: =H32 -> 1434
A33: TOTAL LIABILITIES | B33: =B27+B28+B29+B30+B31+B32 -> 0 | C33: =C27+C28+C29+C30+C31+C32 -> 38962 | D33: =D27+D28+D29+D30+D31+D32 -> 39997 | E33: =E27+E28+E29+E30+E31+E32 -> 39966.373 | F33: =F27+F28+F29+F30+F31+F32 -> 39999.703 | G33: =G27+G28+G29+G30+G31+G32 -> 40066.048 | H33: =H27+H28+H29+H30+H31+H32 -> 40161.401 | I33: =I27+I28+I29+I30+I31+I32 -> 40268.084
A35: EQUITY ($M)
A36: Redeemable noncontrolling interest | C36: 6 | D36: 12 | E36: =D36 -> 12 | F36: =E36 -> 12 | G36: =F36 -> 12 | H36: =G36 -> 12 | I36: =H36 -> 12
A37: Common stock | C37: 12 | D37: 12 | E37: =D37 -> 12 | F37: =E37 -> 12 | G37: =F37 -> 12 | H37: =G37 -> 12 | I37: =H37 -> 12
A38: Additional paid-in capital | C38: 52135 | D38: 51287 | E38: =D38 -> 51287 | F38: =E38 -> 51287 | G38: =F38 -> 51287 | H38: =G38 -> 51287 | I38: =H38 -> 51287
A39: Retained earnings / (deficit) | C39: 2171 | D39: -4629 | E39: =D39+IS!E18-(Assumptions!E36*Assumptions!E37) -> -3820.0425 | F39: =E39+IS!F18-(Assumptions!F36*Assumptions!F37) -> -2967.6719 | G39: =F39+IS!G18-(Assumptions!G36*Assumptions!G37) -> -2001.5749 | H39: =G39+IS!H18-(Assumptions!H36*Assumptions!H37) -> -916.95893 | I39: =H39+IS!I18-(Assumptions!I36*Assumptions!I37) -> 335.98929
A40: Accumulated other comprehensive income / (loss) | C40: -2915 | D40: -2370 | E40: =D40 -> -2370 | F40: =E40 -> -2370 | G40: =F40 -> -2370 | H40: =G40 -> -2370 | I40: =H40 -> -2370
A41: Treasury stock, at cost | C41: -2218 | D41: -2636 | E41: =D41-Assumptions!E38 -> -3136 | F41: =E41-Assumptions!F38 -> -3636 | G41: =F41-Assumptions!G38 -> -4136 | H41: =G41-Assumptions!H38 -> -4636 | I41: =H41-Assumptions!I38 -> -5136
A42: Noncontrolling interest | C42: 134 | D42: 113 | E42: =D42 -> 113 | F42: =E42 -> 113 | G42: =F42 -> 113 | H42: =G42 -> 113 | I42: =H42 -> 113
A43: TOTAL EQUITY | B43: =SUM(B36:B42) -> 0 | C43: =SUM(C36:C42) -> 49325 | D43: =SUM(D36:D42) -> 41789 | E43: =SUM(E36:E42) -> 42097.958 | F43: =SUM(F36:F42) -> 42450.328 | G43: =SUM(G36:G42) -> 42916.425 | H43: =SUM(H36:H42) -> 43501.041 | I43: =SUM(I36:I42) -> 44253.989
A44: TOTAL LIABILITIES AND EQUITY | B44: =B33+B43 -> 0 | C44: =C33+C43 -> 88287 | D44: =D33+D43 -> 81786 | E44: =E33+E43 -> 82064.331 | F44: =F33+F43 -> 82450.031 | G44: =G33+G43 -> 82982.473 | H44: =H33+H43 -> 83662.442 | I44: =I33+I43 -> 84522.074
...

Sheet CFS
A1: CASH FLOW STATEMENT - Consolidated
A3: ($M) | B3: FY2023A | C3: FY2024A | D3: FY2025A | E3: FY2026E | F3: FY2027E | G3: FY2028E | H3: FY2029E | I3: FY2030E
A5: CASH FLOWS FROM OPERATING ACTIVITIES ($M)
A6: Net income / (loss) | B6: 2846 | C6: 2746 | D6: -5848 | E6: =IS!E18 -> 2703.3575 | F6: =IS!F18 -> 2746.7706 | G6: =IS!G18 -> 2860.4969 | H6: =IS!H18 -> 2979.016 | I6: =IS!I18 -> 3147.3482
A7: (+) Depreciation and amortization | B7: 961 | C7: 948 | D7: 968 | E7: =CapEx_DA!E15 -> 965.50207 | F7: =CapEx_DA!F15 -> 973.05605 | G7: =CapEx_DA!G15 -> 961.63509 | H7: =CapEx_DA!H15 -> 979.03213 | I7: =CapEx_DA!I15 -> 972.8051
A8: (+/-) Change in trade receivables | B8: 18 | C8: -139 | D8: -55 | E8: =NWC!E16 -> 23.336973 | F8: =NWC!F16 -> -23.550448 | G8: =NWC!G16 -> -43.629783 | H8: =NWC!H16 -> -56.174394 | I8: =NWC!I16 -> -66.334274
A9: (+/-) Change in inventories | B9: -106 | C9: -6 | D9: 133 | E9: =NWC!E17 -> 54.465904 | F9: =NWC!F17 -> 21.252075 | G9: =NWC!G17 -> -47.489018 | H9: =NWC!H17 -> -21.09052 | I9: =NWC!I17 -> -75.239982
A10: (+/-) Change in accounts payable | B10: -295 | C10: -308 | D10: -97 | E10: =NWC!E18 -> -22.62697 | F10: =NWC!F18 -> 33.329793 | G10: =NWC!G18 -> 66.344952 | H10: =NWC!H18 -> 95.352943 | I10: =NWC!I18 -> 106.68356
A11: (+/-) Other operating items (held flat) | B11: 552 | C11: 943 | D11: 9361 | E11: 0 | F11: 0 | G11: 0 | H11: 0 | I11: 0
A12: Net cash from operating activities | B12: =SUM(B6:B11) -> 3976 | C12: =SUM(C6:C11) -> 4184 | D12: =SUM(D6:D11) -> 4462 | E12: =SUM(E6:E11) -> 3724.0355 | F12: =SUM(F6:F11) -> 3750.8581 | G12: =SUM(G6:G11) -> 3797.3582 | H12: =SUM(H6:H11) -> 3976.1362 | I12: =SUM(I6:I11) -> 4085.2626
A14: CASH FLOWS FROM INVESTING ACTIVITIES ($M)
A15: (-) CapEx | B15: -1013 | C15: -1024 | D15: -801 | E15: =-CapEx_DA!E10 -> -838.86449 | F15: =-CapEx_DA!F10 -> -847.72089 | G15: =-CapEx_DA!G10 -> -838.71279 | H15: =-CapEx_DA!H10 -> -859.21644 | I15: =-CapEx_DA!I10 -> -856.65789
A16: (+/-) Other investing (held flat) | B16: 97 | C16: 1 | D16: -1032 | E16: 144 | F16: 0 | G16: 0 | H16: 0 | I16: 0
A17: Net cash from investing activities | B17: =SUM(B15:B16) -> -916 | C17: =SUM(C15:C16) -> -1023 | D17: =SUM(D15:D16) -> -1833 | E17: =SUM(E15:E16) -> -694.86449 | F17: =SUM(F15:F16) -> -847.72089 | G17: =SUM(G15:G16) -> -838.71279 | H17: =SUM(H15:H16) -> -859.21644 | I17: =SUM(I15:I16) -> -856.65789
A19: CASH FLOWS FROM FINANCING ACTIVITIES ($M)
A20: (+) Proceeds from issuance of long-term debt | B20: 657 | C20: 594 | D20: 1620 | E20: =Debt!E8 -> 1879 | F20: =Debt!F8 -> 1893 | G20: =Debt!G8 -> 1679 | H20: =Debt!H8 -> 1009 | I20: =Debt!I8 -> 915
A21: (-) Repayments of long-term debt | B21: -848 | C21: -618 | D21: -678 | E21: =Debt!E7 -> -1879 | F21: =Debt!F7 -> -1893 | G21: =Debt!G7 -> -1679 | H21: =Debt!H7 -> -1009 | I21: =Debt!I7 -> -915
A22: (-) Dividends paid | B22: -1965 | C22: -1931 | D22: -1898 | E22: =-Assumptions!E36*Assumptions!E37 -> -1894.4 | F22: =-Assumptions!F36*Assumptions!F37 -> -1894.4 | G22: =-Assumptions!G36*Assumptions!G37 -> -1894.4 | H22: =-Assumptions!H36*Assumptions!H37 -> -1894.4 | I22: =-Assumptions!I36*Assumptions!I37 -> -1894.4
A23: (-) Share repurchases | B23: -455 | C23: -988 | D23: -436 | E23: =-Assumptions!E38 -> -500 | F23: =-Assumptions!F38 -> -500 | G23: =-Assumptions!G38 -> -500 | H23: =-Assumptions!H38 -> -500 | I23: =-Assumptions!I38 -> -500
A24: (+/-) Other financing (held flat) | B24: -67 | C24: -65 | D24: 141 | E24: 0 | F24: 0 | G24: 0 | H24: 0 | I24: 0
A25: Net cash from financing activities | B25: =SUM(B20:B24) -> -2678 | C25: =SUM(C20:C24) -> -3008 | D25: =SUM(D20:D24) -> -1251 | E25: =SUM(E20:E24) -> -2394.4 | F25: =SUM(F20:F24) -> -2394.4 | G25: =SUM(G20:G24) -> -2394.4 | H25: =SUM(H20:H24) -> -2394.4 | I25: =SUM(I20:I24) -> -2394.4
A26: CASH RECONCILIATION ($M)
A27: Cash, beginning of period | B27: 991 | C27: 1181 | D27: 1334 | E27: =BS!D6 -> 2615 | F27: =E29 -> 3249.771 | G27: =F29 -> 3758.5082 | H27: =G29 -> 4322.7536 | I27: =H29 -> 5045.2733
A28: Net increase / (decrease) in cash | B28: =B12+B17+B25 -> 382 | C28: =C12+C17+C25 -> 153 | D28: =D12+D17+D25 -> 1378 | E28: =E12+E17+E25 -> 634.77103 | F28: =F12+F17+F25 -> 508.73717 | G28: =G12+G17+G25 -> 564.24538 | H28: =H12+H17+H25 -> 722.51974 | I28: =I12+I17+I25 -> 834.20472
A29: Cash, end of period | B29: =B27+B28 -> 1373 | C29: =C27+C28 -> 1334 | D29: =D27+D28 -> 2712 | E29: =E27+E28 -> 3249.771 | F29: =F27+F28 -> 3758.5082 | G29: =G27+G28 -> 4322.7536 | H29: =H27+H28 -> 5045.2733 | I29: =I27+I28 -> 5879.478
